<mujoco model="puppet">
  <asset>
    <texture type="skybox" builtin="gradient" rgb1="1 1 1" rgb2=".6 .8 1" width="256" height="256"/>
    <texture file="darkWood.png" name="dark-wood"/>
    <material name="wood" reflectance="1.0" texture="dark-wood" texuniform="true"/>
  </asset>
  
  <option gravity="0 0 -9.81"/>
  

  <worldbody>
    <light pos="0 1 1" dir="0 -1 -1" diffuse="1 1 1"/>
    <body name="control1" pos="0 0 3">
      <geom type="box" size="1 0.01 0.01"/>
      <site name="center" pos="0 0 0" size="0.01"/>
      <site name="right" pos="1 0 0" size="0.01"/>
      <site name="left" pos="-1 0 0" size="0.01"/>

      <body name="control2" pos="0 0 0">
        <joint type="hinge" axis="0 0 1"/>
        <geom type="box" size="0.01 1 0.01"/>
        <site name="front" pos="0 1 0" size="0.01"/>
        <site name="back" pos="0 -1 0" size="0.01"/>
      </body>
    </body>

    <body name="body" pos="0 0 1">
      <!-- body definition -->
      <body name="head" pos="0 0 1">
        <geom name="head" material="wood" type="capsule" size="0.1" fromto="0 0 0  0 0 -0.1"/>
        <site name="head_top" pos="0 0 0.1" size="0.01"/>

        <body name="torso" pos="0 0 -0.4">
          <joint axis="0 0 1"/>
          <joint axis="1 0 0"/>
          <geom name="torso_geom" material="wood" type="capsule" size="0.2" fromto="0 0 0  0 0 -0.2"/>
          <site name="end2" pos="0 0 0.2" size="0.01"/>

          <body name="left_arm" pos="-0.2 0 0">
            <joint type="ball"/>
            <geom type="capsule" material="wood" size="0.06" fromto="0 0 0  0 0 -0.4"/>

            <body name="left_elbow_bone" pos="0 0 -0.4">
              <joint type="ball" name="left_elbow_joint"/>
              <geom type="sphere" material="wood" size="0.06"/>
              <site name="left_elbow" pos="-0.06 0 0" size="0.01"/>

              <body pos="0 0 -0.06">
                <joint axis="0 0 1"/>
                <joint axis="1 0 0"/>
                <joint axis="0 1 0"/>
                <geom type="capsule" material="wood" size="0.04" fromto="0 0 0  0 0 -0.3"/>

                <body pos="0 0 -0.3">
                  <joint axis="0 1 0"/>
                  <joint axis="1 0 0"/>
                  <geom pos="-0.1 0 0" material="wood" size="0.1 0.08 0.02" type="ellipsoid"/>
                </body>
              </body>
            </body>
          </body>

          <body name="right_arm" pos="0.2 0 0">
            <joint type="ball"/>
            <geom type="capsule" material="wood" size="0.06" fromto="0 0 0  0 0 -0.4"/>

            <body name="right_elbow_bone" pos="0 0 -0.4">
              <joint type="ball" name="right_elbow_joint"/>
              <geom type="sphere" material="wood" size="0.06"/>
              <site name="right_elbow" pos="0.06 0 0" size="0.01"/>


                <body pos="0 0 -0.06">
                <joint axis="0 0 1"/>
                <joint axis="1 0 0"/>
                <joint axis="0 1 0"/>
                <geom type="capsule" material="wood" size="0.04" fromto="0 0 0  0 0 -0.3"/>

                    <body pos="0 0 -0.3">
                        <joint axis="0 1 0"/>
                        <joint axis="1 0 0"/>
                        <geom pos="0.1 0 0" material="wood" size="0.1 0.08 0.02" type="ellipsoid"/>
                    </body>
                </body>
            </body>
          </body>

          <body name="waist" pos="0 0 -0.4">
            <joint axis="0 0 1"/>
            <joint axis="1 0 0"/>
            <geom type="sphere" material="wood" size="0.1"/>

            <body name="pelvis" pos="0 0 -0.2">
              <joint axis="0 0 1"/>
              <joint axis="1 0 0"/>
              <geom type="capsule" material="wood" size="0.2" fromto="0 0 0  0 0 -0.02"/>

              <body name="pelvis_bone" pos="0 0 -0.1">
                <joint axis="0 0 1"/>
                <joint axis="1 0 0"/>
                <geom type="cylinder" material="wood" size="0.2 0.1"/>
                <site name="left1" pos="-0.08 0 -0.1" size="0.01"/>
                <site name="right1" pos="0.08 0 -0.1" size="0.01"/>

                <body name="left_leg" pos="-0.08 0 -0.1">
                  <joint type="ball"/>
                  <geom type="capsule" material="wood" size="0.07" fromto="0 0 0  0 0 -0.4"/>

                  <body name="left_knee_bone" pos="0 0 -0.4">
                    <joint type="ball" name="left_knee_joint"/>
                    <geom type="sphere" material="wood" size="0.07"/>
                    <site name="left_knee" pos="0 0.07 0" size="0.01"/>

                    <body pos="0 0 -0.07">
                        <joint axis="0 0 1"/>
                        <joint axis="1 0 0"/>
                        <geom type="capsule" material="wood" size="0.05" fromto="0 0 0  0 0 -0.4"/>

                        <body pos="0 0 -0.4">
                        <joint axis="0 1 0"/>
                        <joint axis="1 0 0"/>
                        <geom pos="0.1 0 0" material="wood" size="0.1 0.05 0.02" type="ellipsoid"/>
                        </body>
                    </body>
                  </body>
                </body>

                <body name="right_leg" pos="0.08 0 -0.1">
                  <joint type="ball"/>
                  <geom type="capsule" material="wood" size="0.07" fromto="0 0 0  0 0 -0.4"/>

                  <body name="right_knee_bone" pos="0 0 -0.4">
                    <joint type="ball" name="right_knee_joint"/>
                    <geom type="sphere" material="wood" size="0.07"/>
                    <site name="right_knee" pos="0 -0.07 0" size="0.01"/>

                    <body pos="0 0 -0.07">
                        <joint axis="0 0 1"/>
                        <joint axis="1 0 0"/>
                        <geom type="capsule" material="wood" size="0.05" fromto="0 0 0  0 0 -0.4"/>

                        <body pos="0 0 -0.4">
                        <joint axis="0 1 0"/>
                        <joint axis="1 0 0"/>
                        <geom pos="0.1 0 0" material="wood" size="0.1 0.08 0.02" type="ellipsoid"/>
                        </body>
                    </body>
                  </body>
                </body>
              </body>
            </body>
          </body>
        </body>
      </body>
    </body>
  </worldbody>
  <tendon>
    <spatial limited="true" range="0 .1" width="0.005">
      <site site="center"/>
      <site site="head_top"/>
    </spatial>
    <spatial limited="true" range="0 2" width="0.005">
      <site site="left"/>
      <site site="left_elbow"/>
    </spatial>
    <spatial limited="true" range="0 2" width="0.005">
      <site site="right"/>
      <site site="right_elbow"/>
    </spatial>
    <spatial limited="true" range="0 3" width="0.005">
      <site site="front"/>
      <site site="left_knee"/>
    </spatial>
    <spatial limited="true" range="0 3" width="0.005">
      <site site="back"/>
      <site site="right_knee"/>
    </spatial>
  </tendon>
  <actuator>
    <!-- Actuator for the left elbow joint -->
    <velocity name="left elbow servo" joint="left_elbow_joint" kv="10"/>
    <!-- Actuator for the right elbow joint -->
    <velocity name="right elbow servo" joint="right_elbow_joint" kv="10"/>
    <!-- Actuator for the left knee joint -->
    <velocity name="left knee servo" joint="left_knee_joint" kv="10"/>
    <!-- Actuator for the right knee joint -->
    <velocity name="right knee servo" joint="right_knee_joint" kv="10"/>
    <position name="tendon_length_control" site="front" kp="100"/>
  </actuator>
</mujoco>